Workbook

Sheet Orders
A1: order_id | B1: customer_id | C1: order_status | D1: order_date | E1: required_date | F1: shipped_date | G1: store_id | H1: staff_id | I1: customer name | J1: customer state | K1: customer city | L1: staff name | M1: store name | N1: store city | O1: store state
A2: 1 | B2: 259 | C2: 4 | D2: 42370 | E2: 42372 | F2: 42372 | G2: 1 | H2: 2 | I2: =VLOOKUP(B2,Customers!A:J, 10,FALSE) -> Johnathan Velazquez | J2: =VLOOKUP(B2,Customers!A:J,8,FALSE) -> CA | K2: =VLOOKUP(B2,Customers!A:J,7,FALSE) -> Pleasanton | L2: =VLOOKUP(H2,Staff!A:I,9,FALSE) -> Mireya Copeland | M2: =VLOOKUP(G2,Store!A:H,2,FALSE) -> Santa Cruz Bikes | N2: =VLOOKUP(G2,Store!A:H,6,FALSE) -> Santa Cruz | O2: CA
A3: 2 | B3: 1212 | C3: 4 | D3: 42370 | E3: 42373 | F3: 42372 | G3: 2 | H3: 6 | I3: =VLOOKUP(B3,Customers!A:J, 10,FALSE) -> Jaqueline Cummings | J3: =VLOOKUP(B3,Customers!A:J,8,FALSE) -> NY | K3: =VLOOKUP(B3,Customers!A:J,7,FALSE) -> Huntington Station | L3: =VLOOKUP(H3,Staff!A:I,9,FALSE) -> Marcelene Boyer | M3: =VLOOKUP(G3,Store!A:H,2,FALSE) -> Baldwin Bikes | N3: =VLOOKUP(G3,Store!A:H,6,FALSE) -> Baldwin | O3: NY
A4: 3 | B4: 523 | C4: 4 | D4: 42371 | E4: 42374 | F4: 42372 | G4: 2 | H4: 7 | I4: =VLOOKUP(B4,Customers!A:J, 10,FALSE) -> Joshua Robertson | J4: =VLOOKUP(B4,Customers!A:J,8,FALSE) -> NY | K4: =VLOOKUP(B4,Customers!A:J,7,FALSE) -> Patchogue | L4: =VLOOKUP(H4,Staff!A:I,9,FALSE) -> Venita Daniel | M4: =VLOOKUP(G4,Store!A:H,2,FALSE) -> Baldwin Bikes | N4: =VLOOKUP(G4,Store!A:H,6,FALSE) -> Baldwin | O4: NY
A5: 4 | B5: 175 | C5: 4 | D5: 42372 | E5: 42373 | F5: 42374 | G5: 1 | H5: 3 | I5: =VLOOKUP(B5,Customers!A:J, 10,FALSE) -> Nova Hess | J5: =VLOOKUP(B5,Customers!A:J,8,FALSE) -> CA | K5: =VLOOKUP(B5,Customers!A:J,7,FALSE) -> Duarte | L5: =VLOOKUP(H5,Staff!A:I,9,FALSE) -> Genna Serrano | M5: =VLOOKUP(G5,Store!A:H,2,FALSE) -> Santa Cruz Bikes | N5: =VLOOKUP(G5,Store!A:H,6,FALSE) -> Santa Cruz | O5: CA
A6: 5 | B6: 1324 | C6: 4 | D6: 42372 | E6: 42375 | F6: 42375 | G6: 2 | H6: 6 | I6: =VLOOKUP(B6,Customers!A:J, 10,FALSE) -> Arla Ellis | J6: =VLOOKUP(B6,Customers!A:J,8,FALSE) -> NY | K6: =VLOOKUP(B6,Customers!A:J,7,FALSE) -> Utica | L6: =VLOOKUP(H6,Staff!A:I,9,FALSE) -> Marcelene Boyer | M6: =VLOOKUP(G6,Store!A:H,2,FALSE) -> Baldwin Bikes | N6: =VLOOKUP(G6,Store!A:H,6,FALSE) -> Baldwin | O6: NY
A7: 6 | B7: 94 | C7: 4 | D7: 42373 | E7: 42376 | F7: 42374 | G7: 2 | H7: 6 | I7: =VLOOKUP(B7,Customers!A:J, 10,FALSE) -> Sharyn Hopkins | J7: =VLOOKUP(B7,Customers!A:J,8,FALSE) -> NY | K7: =VLOOKUP(B7,Customers!A:J,7,FALSE) -> Baldwinsville | L7: =VLOOKUP(H7,Staff!A:I,9,FALSE) -> Marcelene Boyer | M7: =VLOOKUP(G7,Store!A:H,2,FALSE) -> Baldwin Bikes | N7: =VLOOKUP(G7,Store!A:H,6,FALSE) -> Baldwin | O7: NY
A8: 7 | B8: 324 | C8: 4 | D8: 42373 | E8: 42376 | F8: 42374 | G8: 2 | H8: 6 | I8: =VLOOKUP(B8,Customers!A:J, 10,FALSE) -> Laureen Paul | J8: =VLOOKUP(B8,Customers!A:J,8,FALSE) -> NY | K8: =VLOOKUP(B8,Customers!A:J,7,FALSE) -> Bellmore | L8: =VLOOKUP(H8,Staff!A:I,9,FALSE) -> Marcelene Boyer | M8: =VLOOKUP(G8,Store!A:H,2,FALSE) -> Baldwin Bikes | N8: =VLOOKUP(G8,Store!A:H,6,FALSE) -> Baldwin | O8: NY
A9: 8 | B9: 1204 | C9: 4 | D9: 42373 | E9: 42374 | F9: 42374 | G9: 2 | H9: 7 | I9: =VLOOKUP(B9,Customers!A:J, 10,FALSE) -> Leslie Higgins | J9: =VLOOKUP(B9,Customers!A:J,8,FALSE) -> NY | K9: =VLOOKUP(B9,Customers!A:J,7,FALSE) -> Saratoga Springs | L9: =VLOOKUP(H9,Staff!A:I,9,FALSE) -> Venita Daniel | M9: =VLOOKUP(G9,Store!A:H,2,FALSE) -> Baldwin Bikes | N9: =VLOOKUP(G9,Store!A:H,6,FALSE) -> Baldwin | O9: NY
A10: 9 | B10: 60 | C10: 4 | D10: 42374 | E10: 42377 | F10: 42377 | G10: 1 | H10: 2 | I10: =VLOOKUP(B10,Customers!A:J, 10,FALSE) -> Neil Mccall | J10: =VLOOKUP(B10,Customers!A:J,8,FALSE) -> CA | K10: =VLOOKUP(B10,Customers!A:J,7,FALSE) -> San Carlos | L10: =VLOOKUP(H10,Staff!A:I,9,FALSE) -> Mireya Copeland | M10: =VLOOKUP(G10,Store!A:H,2,FALSE) -> Santa Cruz Bikes | N10: =VLOOKUP(G10,Store!A:H,6,FALSE) -> Santa Cruz | O10: CA
A11: 10 | B11: 442 | C11: 4 | D11: 42374 | E11: 42375 | F11: 42375 | G11: 2 | H11: 6 | I11: =VLOOKUP(B11,Customers!A:J, 10,FALSE) -> Alane Munoz | J11: =VLOOKUP(B11,Customers!A:J,8,FALSE) -> NY | K11: =VLOOKUP(B11,Customers!A:J,7,FALSE) -> Yonkers | L11: =VLOOKUP(H11,Staff!A:I,9,FALSE) -> Marcelene Boyer | M11: =VLOOKUP(G11,Store!A:H,2,FALSE) -> Baldwin Bikes | N11: =VLOOKUP(G11,Store!A:H,6,FALSE) -> Baldwin | O11: NY
A12: 11 | B12: 1326 | C12: 4 | D12: 42374 | E12: 42377 | F12: 42376 | G12: 2 | H12: 7 | I12: =VLOOKUP(B12,Customers!A:J, 10,FALSE) -> Tarra Guerrero | J12: =VLOOKUP(B12,Customers!A:J,8,FALSE) -> NY | K12: =VLOOKUP(B12,Customers!A:J,7,FALSE) -> Auburn | L12: =VLOOKUP(H12,Staff!A:I,9,FALSE) -> Venita Daniel | M12: =VLOOKUP(G12,Store!A:H,2,FALSE) -> Baldwin Bikes | N12: =VLOOKUP(G12,Store!A:H,6,FALSE) -> Baldwin | O12: NY
A13: 12 | B13: 91 | C13: 4 | D13: 42375 | E13: 42377 | F13: 42378 | G13: 1 | H13: 2 | I13: =VLOOKUP(B13,Customers!A:J, 10,FALSE) -> Marvin Mullins | J13: =VLOOKUP(B13,Customers!A:J,8,FALSE) -> CA | K13: =VLOOKUP(B13,Customers!A:J,7,FALSE) -> San Diego | L13: =VLOOKUP(H13,Staff!A:I,9,FALSE) -> Mireya Copeland | M13: =VLOOKUP(G13,Store!A:H,2,FALSE) -> Santa Cruz Bikes | N13: =VLOOKUP(G13,Store!A:H,6,FALSE) -> Santa Cruz | O13: CA
... A70: 69 | B70: 1413 | C70: 4 | D70: 42410 | E70: 42412 | F70: 42411 | G70: 2 | H70: 7 | I70: =VLOOKUP(B70,Customers!A:J, 10,FALSE) -> Ophelia Decker | J70: =VLOOKUP(B70,Customers!A:J,8,FALSE) -> NY | K70: =VLOOKUP(B70,Customers!A:J,7,FALSE) -> New Windsor | L70: =VLOOKUP(H70,Staff!A:I,9,FALSE) -> Venita Daniel | M70: =VLOOKUP(G70,Store!A:H,2,FALSE) -> Baldwin Bikes | N70: =VLOOKUP(G70,Store!A:H,6,FALSE) -> Baldwin | O70: NY
A71: 70 | B71: 50 | C71: 3 | D71: 42411 | E71: 42411 | F71: NULL | G71: 3 | H71: 9 | I71: =VLOOKUP(B71,Customers!A:J, 10,FALSE) -> Cleotilde Booth | J71: =VLOOKUP(B71,Customers!A:J,8,FALSE) -> TX | K71: =VLOOKUP(B71,Customers!A:J,7,FALSE) -> Sugar Land | L71: =VLOOKUP(H71,Staff!A:I,9,FALSE) -> Layla Terrell | M71: =VLOOKUP(G71,Store!A:H,2,FALSE) -> Rowlett Bikes | N71: =VLOOKUP(G71,Store!A:H,6,FALSE) -> Rowlett | O71: TX
A72: 71 | B72: 797 | C72: 4 | D72: 42411 | E72: 42414 | F72: 42412 | G72: 2 | H72: 7 | I72: =VLOOKUP(B72,Customers!A:J, 10,FALSE) -> Cathey Lamb | J72: =VLOOKUP(B72,Customers!A:J,8,FALSE) -> NY | K72: =VLOOKUP(B72,Customers!A:J,7,FALSE) -> Bayside | L72: =VLOOKUP(H72,Staff!A:I,9,FALSE) -> Venita Daniel | M72: =VLOOKUP(G72,Store!A:H,2,FALSE) -> Baldwin Bikes | N72: =VLOOKUP(G72,Store!A:H,6,FALSE) -> Baldwin | O72: NY
A73: 72 | B73: 1386 | C73: 4 | D73: 42412 | E73: 42415 | F73: 42413 | G73: 1 | H73: 2 | I73: =VLOOKUP(B73,Customers!A:J, 10,FALSE) -> Cesar Wilkins | J73: =VLOOKUP(B73,Customers!A:J,8,FALSE) -> CA | K73: =VLOOKUP(B73,Customers!A:J,7,FALSE) -> San Diego | L73: =VLOOKUP(H73,Staff!A:I,9,FALSE) -> Mireya Copeland | M73: =VLOOKUP(G73,Store!A:H,2,FALSE) -> Santa Cruz Bikes | N73: =VLOOKUP(G73,Store!A:H,6,FALSE) -> Santa Cruz | O73: CA
A74: 73 | B74: 612 | C74: 4 | D74: 42412 | E74: 42415 | F74: 42414 | G74: 2 | H74: 7 | I74: =VLOOKUP(B74,Customers!A:J, 10,FALSE) -> Gabriel Wagner | J74: =VLOOKUP(B74,Customers!A:J,8,FALSE) -> NY | K74: =VLOOKUP(B74,Customers!A:J,7,FALSE) -> Ballston Spa | L74: =VLOOKUP(H74,Staff!A:I,9,FALSE) -> Venita Daniel | M74: =VLOOKUP(G74,Store!A:H,2,FALSE) -> Baldwin Bikes | N74: =VLOOKUP(G74,Store!A:H,6,FALSE) -> Baldwin | O74: NY
A75: 74 | B75: 264 | C75: 4 | D75: 42413 | E75: 42415 | F75: 42415 | G75: 2 | H75: 7 | I75: =VLOOKUP(B75,Customers!A:J, 10,FALSE) -> Mariela Huffman | J75: =VLOOKUP(B75,Customers!A:J,8,FALSE) -> NY | K75: =VLOOKUP(B75,Customers!A:J,7,FALSE) -> Garden City | L75: =VLOOKUP(H75,Staff!A:I,9,FALSE) -> Venita Daniel | M75: =VLOOKUP(G75,Store!A:H,2,FALSE) -> Baldwin Bikes | N75: =VLOOKUP(G75,Store!A:H,6,FALSE) -> Baldwin | O75: NY
A76: 75 | B76: 587 | C76: 4 | D76: 42414 | E76: 42415 | F76: 42417 | G76: 2 | H76: 6 | I76: =VLOOKUP(B76,Customers!A:J, 10,FALSE) -> Euna Lopez | J76: =VLOOKUP(B76,Customers!A:J,8,FALSE) -> NY | K76: =VLOOKUP(B76,Customers!A:J,7,FALSE) -> Carmel | L76: =VLOOKUP(H76,Staff!A:I,9,FALSE) -> Marcelene Boyer | M76: =VLOOKUP(G76,Store!A:H,2,FALSE) -> Baldwin Bikes | N76: =VLOOKUP(G76,Store!A:H,6,FALSE) -> Baldwin | O76: NY
A77: 76 | B77: 9 | C77: 3 | D77: 42416 | E77: 42416 | F77: NULL | G77: 2 | H77: 6 | I77: =VLOOKUP(B77,Customers!A:J, 10,FALSE) -> Genoveva Baldwin | J77: =VLOOKUP(B77,Customers!A:J,8,FALSE) -> NY | K77: =VLOOKUP(B77,Customers!A:J,7,FALSE) -> Port Washington | L77: =VLOOKUP(H77,Staff!A:I,9,FALSE) -> Marcelene Boyer | M77: =VLOOKUP(G77,Store!A:H,2,FALSE) -> Baldwin Bikes | N77: =VLOOKUP(G77,Store!A:H,6,FALSE) -> Baldwin | O77: NY
A78: 77 | B78: 385 | C78: 4 | D78: 42416 | E78: 42419 | F78: 42419 | G78: 1 | H78: 2 | I78: =VLOOKUP(B78,Customers!A:J, 10,FALSE) -> Rochelle Ward | J78: =VLOOKUP(B78,Customers!A:J,8,FALSE) -> CA | K78: =VLOOKUP(B78,Customers!A:J,7,FALSE) -> Glendora | L78: =VLOOKUP(H78,Staff!A:I,9,FALSE) -> Mireya Copeland | M78: =VLOOKUP(G78,Store!A:H,2,FALSE) -> Santa Cruz Bikes | N78: =VLOOKUP(G78,Store!A:H,6,FALSE) -> Santa Cruz | O78: CA
A79: 78 | B79: 1182 | C79: 4 | D79: 42416 | E79: 42418 | F79: 42419 | G79: 2 | H79: 7 | I79: =VLOOKUP(B79,Customers!A:J, 10,FALSE) -> Trinidad Chapman | J79: =VLOOKUP(B79,Customers!A:J,8,FALSE) -> NY | K79: =VLOOKUP(B79,Customers!A:J,7,FALSE) -> Ronkonkoma | L79: =VLOOKUP(H79,Staff!A:I,9,FALSE) -> Venita Daniel | M79: =VLOOKUP(G79,Store!A:H,2,FALSE) -> Baldwin Bikes | N79: =VLOOKUP(G79,Store!A:H,6,FALSE) -> Baldwin | O79: NY
A80: 79 | B80: 529 | C80: 4 | D80: 42417 | E80: 42420 | F80: 42420 | G80: 1 | H80: 3 | I80: =VLOOKUP(B80,Customers!A:J, 10,FALSE) -> Ellena Clements | J80: =VLOOKUP(B80,Customers!A:J,8,FALSE) -> CA | K80: =VLOOKUP(B80,Customers!A:J,7,FALSE) -> Santa Monica | L80: =VLOOKUP(H80,Staff!A:I,9,FALSE) -> Genna Serrano | M80: =VLOOKUP(G80,Store!A:H,2,FALSE) -> Santa Cruz Bikes | N80: =VLOOKUP(G80,Store!A:H,6,FALSE) -> Santa Cruz | O80: CA
A81: 80 | B81: 397 | C81: 4 | D81: 42417 | E81: 42420 | F81: 42419 | G81: 2 | H81: 6 | I81: =VLOOKUP(B81,Customers!A:J, 10,FALSE) -> Jeannie Wilcox | J81: =VLOOKUP(B81,Customers!A:J,8,FALSE) -> NY | K81: =VLOOKUP(B81,Customers!A:J,7,FALSE) -> Franklin Square | L81: =VLOOKUP(H81,Staff!A:I,9,FALSE) -> Marcelene Boyer | M81: =VLOOKUP(G81,Store!A:H,2,FALSE) -> Baldwin Bikes | N81: =VLOOKUP(G81,Store!A:H,6,FALSE) -> Baldwin | O81: NY
A82: 81 | B82: 521 | C82: 4 | D82: 42417 | E82: 42419 | F82: 42418 | G82: 2 | H82: 6 | I82: =VLOOKUP(B82,Customers!A:J, 10,FALSE) -> Max Charles | J82: =VLOOKUP(B82,Customers!A:J,8,FALSE) -> NY | K82: =VLOOKUP(B82,Customers!A:J,7,FALSE) -> Glen Cove | L82: =VLOOKUP(H82,Staff!A:I,9,FALSE) -> Marcelene Boyer | M82: =VLOOKUP(G82,Store!A:H,2,FALSE) -> Baldwin Bikes | N82: =VLOOKUP(G82,Store!A:H,6,FALSE) -> Baldwin | O82: NY
A83: 82 | B83: 1223 | C83: 4 | D83: 42418 | E83: 42421 | F83: 42420 | G83: 2 | H83: 6 | I83: =VLOOKUP(B83,Customers!A:J, 10,FALSE) -> Bronwyn Vargas | J83: =VLOOKUP(B83,Customers!A:J,8,FALSE) -> NY | K83: =VLOOKUP(B83,Customers!A:J,7,FALSE) -> New Windsor | L83: =VLOOKUP(H83,Staff!A:I,9,FALSE) -> Marcelene Boyer | M83: =VLOOKUP(G83,Store!A:H,2,FALSE) -> Baldwin Bikes | N83: =VLOOKUP(G83,Store!A:H,6,FALSE) -> Baldwin | O83: NY
A84: 83 | B84: 393 | C84: 4 | D84: 42419 | E84: 42420 | F84: 42420 | G84: 1 | H84: 3 | I84: =VLOOKUP(B84,Customers!A:J, 10,FALSE) -> Gertrude Terry | J84: =VLOOKUP(B84,Customers!A:J,8,FALSE) -> CA | K84: =VLOOKUP(B84,Customers!A:J,7,FALSE) -> Upland | L84: =VLOOKUP(H84,Staff!A:I,9,FALSE) -> Genna Serrano | M84: =VLOOKUP(G84,Store!A:H,2,FALSE) -> Santa Cruz Bikes | N84: =VLOOKUP(G84,Store!A:H,6,FALSE) -> Santa Cruz | O84: CA
A85: 84 | B85: 317 | C85: 4 | D85: 42420 | E85: 42422 | F85: 42421 | G85: 2 | H85: 7 | I85: =VLOOKUP(B85,Customers!A:J, 10,FALSE) -> Christia Wilkins | J85: =VLOOKUP(B85,Customers!A:J,8,FALSE) -> NY | K85: =VLOOKUP(B85,Customers!A:J,7,FALSE) -> Woodside | L85: =VLOOKUP(H85,Staff!A:I,9,FALSE) -> Venita Daniel | M85: =VLOOKUP(G85,Store!A:H,2,FALSE) -> Baldwin Bikes | N85: =VLOOKUP(G85,Store!A:H,6,FALSE) -> Baldwin | O85: NY
A86: 85 | B86: 1174 | C86: 4 | D86: 42420 | E86: 42423 | F86: 42421 | G86: 2 | H86: 7 | I86: =VLOOKUP(B86,Customers!A:J, 10,FALSE) -> Aaron Knapp | J86: =VLOOKUP(B86,Customers!A:J,8,FALSE) -> NY | K86: =VLOOKUP(B86,Customers!A:J,7,FALSE) -> Yonkers | L86: =VLOOKUP(H86,Staff!A:I,9,FALSE) -> Venita Daniel | M86: =VLOOKUP(G86,Store!A:H,2,FALSE) -> Baldwin Bikes | N86: =VLOOKUP(G86,Store!A:H,6,FALSE) -> Baldwin | O86: NY
A87: 86 | B87: 276 | C87: 4 | D87: 42421 | E87: 42422 | F87: 42423 | G87: 2 | H87: 7 | I87: =VLOOKUP(B87,Customers!A:J, 10,FALSE) -> Lavette Wright | J87: =VLOOKUP(B87,Customers!A:J,8,FALSE) -> NY | K87: =VLOOKUP(B87,Customers!A:J,7,FALSE) -> Ronkonkoma | L87: =VLOOKUP(H87,Staff!A:I,9,FALSE) -> Venita Daniel | M87: =VLOOKUP(G87,Store!A:H,2,FALSE) -> Baldwin Bikes | N87: =VLOOKUP(G87,Store!A:H,6,FALSE) -> Baldwin | O87: NY
A88: 87 | B88: 516 | C88: 4 | D88: 42421 | E88: 42422 | F88: 42423 | G88: 2 | H88: 6 | I88: =VLOOKUP(B88,Customers!A:J, 10,FALSE) -> Rosa Kinney | J88: =VLOOKUP(B88,Customers!A:J,8,FALSE) -> NY | K88: =VLOOKUP(B88,Customers!A:J,7,FALSE) -> Brooklyn | L88: =VLOOKUP(H88,Staff!A:I,9,FALSE) -> Marcelene Boyer | M88: =VLOOKUP(G88,Store!A:H,2,FALSE) -> Baldwin Bikes | N88: =VLOOKUP(G88,Store!A:H,6,FALSE) -> Baldwin | O88: NY
A89: 88 | B89: 1069 | C89: 4 | D89: 42421 | E89: 42422 | F89: 42423 | G89: 2 | H89: 6 | I89: =VLOOKUP(B89,Customers!A:J, 10,FALSE) -> Rodolfo Buck | J89: =VLOOKUP(B89,Customers!A:J,8,FALSE) -> NY | K89: =VLOOKUP(B89,Customers!A:J,7,FALSE) -> Shirley | L89: =VLOOKUP(H89,Staff!A:I,9,FALSE) -> Marcelene Boyer | M89: =VLOOKUP(G89,Store!A:H,2,FALSE) -> Baldwin Bikes | N89: =VLOOKUP(G89,Store!A:H,6,FALSE) -> Baldwin | O89: NY
... A158: 157 | B158: 43 | C158: 4 | D158: 42463 | E158: 42466 | F158: 42466 | G158: 3 | H158: 8 | I158: =VLOOKUP(B158,Customers!A:J, 10,FALSE) -> Mozelle Carter | J158: =VLOOKUP(B158,Customers!A:J,8,FALSE) -> TX | K158: =VLOOKUP(B158,Customers!A:J,7,FALSE) -> Houston | L158: =VLOOKUP(H158,Staff!A:I,9,FALSE) -> Kali Vargas | M158: =VLOOKUP(G158,Store!A:H,2,FALSE) -> Rowlett Bikes | N158: =VLOOKUP(G158,Store!A:H,6,FALSE) -> Rowlett | O158: TX
A159: 158 | B159: 117 | C159: 3 | D159: 42464 | E159: 42464 | F159: NULL | G159: 3 | H159: 9 | I159: =VLOOKUP(B159,Customers!A:J, 10,FALSE) -> Dacia William | J159: =VLOOKUP(B159,Customers!A:J,8,FALSE) -> TX | K159: =VLOOKUP(B159,Customers!A:J,7,FALSE) -> Sugar Land | L159: =VLOOKUP(H159,Staff!A:I,9,FALSE) -> Layla Terrell | M159: =VLOOKUP(G159,Store!A:H,2,FALSE) -> Rowlett Bikes | N159: =VLOOKUP(G159,Store!A:H,6,FALSE) -> Rowlett | O159: TX
A160: 159 | B160: 32 | C160: 4 | D160: 42464 | E160: 42466 | F160: 42466 | G160: 1 | H160: 2 | I160: =VLOOKUP(B160,Customers!A:J, 10,FALSE) -> Araceli Golden | J160: =VLOOKUP(B160,Customers!A:J,8,FALSE) -> CA | K160: =VLOOKUP(B160,Customers!A:J,7,FALSE) -> Fullerton | L160: =VLOOKUP(H160,Staff!A:I,9,FALSE) -> Mireya Copeland | M160: =VLOOKUP(G160,Store!A:H,2,FALSE) -> Santa Cruz Bikes | N160: =VLOOKUP(G160,Store!A:H,6,FALSE) -> Santa Cruz | O160: CA
A161: 160 | B161: 205 | C161: 4 | D161: 42464 | E161: 42466 | F161: 42466 | G161: 2 | H161: 7 | I161: =VLOOKUP(B161,Customers!A:J, 10,FALSE) -> Harris Pittman | J161: =VLOOKUP(B161,Customers!A:J,8,FALSE) -> NY | K161: =VLOOKUP(B161,Customers!A:J,7,FALSE) -> Jamaica | L161: =VLOOKUP(H161,Staff!A:I,9,FALSE) -> Venita Daniel | M161: =VLOOKUP(G161,Store!A:H,2,FALSE) -> Baldwin Bikes | N161: =VLOOKUP(G161,Store!A:H,6,FALSE) -> Baldwin | O161: NY
A162: 161 | B162: 251 | C162: 4 | D162: 42464 | E162: 42467 | F162: 42465 | G162: 2 | H162: 7 | I162: =VLOOKUP(B162,Customers!A:J, 10,FALSE) -> Kasie Rodriquez | J162: =VLOOKUP(B162,Customers!A:J,8,FALSE) -> NY | K162: =VLOOKUP(B162,Customers!A:J,7,FALSE) -> Ballston Spa | L162: =VLOOKUP(H162,Staff!A:I,9,FALSE) -> Venita Daniel | M162: =VLOOKUP(G162,Store!A:H,2,FALSE) -> Baldwin Bikes | N162: =VLOOKUP(G162,Store!A:H,6,FALSE) -> Baldwin | O162: NY
A163: 162 | B163: 31 | C163: 4 | D163: 42466 | E163: 42468 | F163: 42467 | G163: 1 | H163: 3 | I163: =VLOOKUP(B163,Customers!A:J, 10,FALSE) -> Williemae Holloway | J163: =VLOOKUP(B163,Customers!A:J,8,FALSE) -> CA | K163: =VLOOKUP(B163,Customers!A:J,7,FALSE) -> Oakland | L163: =VLOOKUP(H163,Staff!A:I,9,FALSE) -> Genna Serrano | M163: =VLOOKUP(G163,Store!A:H,2,FALSE) -> Santa Cruz Bikes | N163: =VLOOKUP(G163,Store!A:H,6,FALSE) -> Santa Cruz | O163: CA
A164: 163 | B164: 1325 | C164: 4 | D164: 42466 | E164: 42467 | F164: 42467 | G164: 2 | H164: 7 | I164: =VLOOKUP(B164,Customers!A:J, 10,FALSE) -> Magdalena Sherman | J164: =VLOOKUP(B164,Customers!A:J,8,FALSE) -> NY | K164: =VLOOKUP(B164,Customers!A:J,7,FALSE) -> Oswego | L164: =VLOOKUP(H164,Staff!A:I,9,FALSE) -> Venita Daniel | M164: =VLOOKUP(G164,Store!A:H,2,FALSE) -> Baldwin Bikes | N164: =VLOOKUP(G164,Store!A:H,6,FALSE) -> Baldwin | O164: NY
...

Sheet Pivot Table
Q1: Total Order Id by Store Name / State | R1: store state
Q2: Store name | R2: CA | S2: NY | T2: TX
Q4: Baldwin Bikes | S4: 1093
Q5: Rowlett Bikes | T5: 174
Q6: Santa Cruz Bikes | R6: 348
Q7: Grand Total | R7: 348 | S7: 1093 | T7: 174

Sheet Pivot Chart

Sheet Customers
A1: customer_id | B1: first_name | C1: last_name | D1: phone | E1: email | F1: street | G1: city | H1: state | I1: zip_code | J1: customer name
A2: 1 | B2: Debra | C2: Burks | D2: NULL | E2: debra.burks@yahoo.com | F2: 9273 Thorne Ave. | G2: Orchard Park | H2: NY | I2: 14127 | J2: =CONCATENATE(B2," ",C2) -> Debra Burks
A3: 2 | B3: Kasha | C3: Todd | D3: NULL | E3: kasha.todd@yahoo.com | F3: 910 Vine Street | G3: Campbell | H3: CA | I3: 95008 | J3: =CONCATENATE(B3," ",C3) -> Kasha Todd
A4: 3 | B4: Tameka | C4: Fisher | D4: NULL | E4: tameka.fisher@aol.com | F4: 769C Honey Creek St. | G4: Redondo Beach | H4: CA | I4: 90278 | J4: =CONCATENATE(B4," ",C4) -> Tameka Fisher
A5: 4 | B5: Daryl | C5: Spence | D5: NULL | E5: daryl.spence@aol.com | F5: 988 Pearl Lane | G5: Uniondale | H5: NY | I5: 11553 | J5: =CONCATENATE(B5," ",C5) -> Daryl Spence
A6: 5 | B6: Charolette | C6: Rice | D6: (916) 381-6003 | E6: charolette.rice@msn.com | F6: 107 River Dr. | G6: Sacramento | H6: CA | I6: 95820 | J6: =CONCATENATE(B6," ",C6) -> Charolette Rice
A7: 6 | B7: Lyndsey | C7: Bean | D7: NULL | E7: lyndsey.bean@hotmail.com | F7: 769 West Road | G7: Fairport | H7: NY | I7: 14450 | J7: =CONCATENATE(B7," ",C7) -> Lyndsey Bean
A8: 7 | B8: Latasha | C8: Hays | D8: (716) 986-3359 | E8: latasha.hays@hotmail.com | F8: 7014 Manor Station Rd. | G8: Buffalo | H8: NY | I8: 14215 | J8: =CONCATENATE(B8," ",C8) -> Latasha Hays
A9: 8 | B9: Jacquline | C9: Duncan | D9: NULL | E9: jacquline.duncan@yahoo.com | F9: 15 Brown St. | G9: Jackson Heights | H9: NY | I9: 11372 | J9: =CONCATENATE(B9," ",C9) -> Jacquline Duncan
A10: 9 | B10: Genoveva | C10: Baldwin | D10: NULL | E10: genoveva.baldwin@msn.com | F10: 8550 Spruce Drive | G10: Port Washington | H10: NY | I10: 11050 | J10: =CONCATENATE(B10," ",C10) -> Genoveva Baldwin
A11: 10 | B11: Pamelia | C11: Newman | D11: NULL | E11: pamelia.newman@gmail.com | F11: 476 Chestnut Ave. | G11: Monroe | H11: NY | I11: 10950 | J11: =CONCATENATE(B11," ",C11) -> Pamelia Newman
A12: 11 | B12: Deshawn | C12: Mendoza | D12: NULL | E12: deshawn.mendoza@yahoo.com | F12: 8790 Cobblestone Street | G12: Monsey | H12: NY | I12: 10952 | J12: =CONCATENATE(B12," ",C12) -> Deshawn Mendoza
A13: 12 | B13: Robby | C13: Sykes | D13: (516) 583-7761 | E13: robby.sykes@hotmail.com | F13: 486 Rock Maple Street | G13: Hempstead | H13: NY | I13: 11550 | J13: =CONCATENATE(B13," ",C13) -> Robby Sykes
... A1446: 1445 | B1446: Ester | C1446: Acevedo | D1446: NULL | E1446: ester.acevedo@gmail.com | F1446: 671 Miles Court | G1446: San Lorenzo | H1446: CA | I1446: 94580 | J1446: =CONCATENATE(B1446," ",C1446) -> Ester Acevedo

Sheet Store
A1: store_id | B1: store_name | C1: phone | D1: email | E1: street | F1: city | G1: state | H1: zip_code
A2: 1 | B2: Santa Cruz Bikes | C2: (831) 476-4321 | D2: santacruz@bikes.shop | E2: 3700 Portola Drive | F2: Santa Cruz | G2: CA | H2: 95060
A3: 2 | B3: Baldwin Bikes | C3: (516) 379-8888 | D3: baldwin@bikes.shop | E3: 4200 Chestnut Lane | F3: Baldwin | G3: NY | H3: 11432
A4: 3 | B4: Rowlett Bikes | C4: (972) 530-5555 | D4: rowlett@bikes.shop | E4: 8000 Fairway Avenue | F4: Rowlett | G4: TX | H4: 75088

Sheet Staff
A1: staff_id | B1: first_name | C1: last_name | D1: email | E1: phone | F1: active | G1: store_id | H1: manager_id | I1: staff name
A2: 1 | B2: Fabiola | C2: Jackson | D2: fabiola.jackson@bikes.shop | E2: (831) 555-5554 | F2: 1 | G2: 1 | H2: NULL | I2: =CONCATENATE(B2," ",C2) -> Fabiola Jackson
A3: 2 | B3: Mireya | C3: Copeland | D3: mireya.copeland@bikes.shop | E3: (831) 555-5555 | F3: 1 | G3: 1 | H3: 1 | I3: =CONCATENATE(B3," ",C3) -> Mireya Copeland
A4: 3 | B4: Genna | C4: Serrano | D4: genna.serrano@bikes.shop | E4: (831) 555-5556 | F4: 1 | G4: 1 | H4: 2 | I4: =CONCATENATE(B4," ",C4) -> Genna Serrano
A5: 4 | B5: Virgie | C5: Wiggins | D5: virgie.wiggins@bikes.shop | E5: (831) 555-5557 | F5: 1 | G5: 1 | H5: 2 | I5: =CONCATENATE(B5," ",C5) -> Virgie Wiggins
A6: 5 | B6: Jannette | C6: David | D6: jannette.david@bikes.shop | E6: (516) 379-4444 | F6: 1 | G6: 2 | H6: 1 | I6: =CONCATENATE(B6," ",C6) -> Jannette David
A7: 6 | B7: Marcelene | C7: Boyer | D7: marcelene.boyer@bikes.shop | E7: (516) 379-4445 | F7: 1 | G7: 2 | H7: 5 | I7: =CONCATENATE(B7," ",C7) -> Marcelene Boyer
A8: 7 | B8: Venita | C8: Daniel | D8: venita.daniel@bikes.shop | E8: (516) 379-4446 | F8: 1 | G8: 2 | H8: 5 | I8: =CONCATENATE(B8," ",C8) -> Venita Daniel
A9: 8 | B9: Kali | C9: Vargas | D9: kali.vargas@bikes.shop | E9: (972) 530-5555 | F9: 1 | G9: 3 | H9: 1 | I9: =CONCATENATE(B9," ",C9) -> Kali Vargas
A10: 9 | B10: Layla | C10: Terrell | D10: layla.terrell@bikes.shop | E10: (972) 530-5556 | F10: 1 | G10: 3 | H10: 7 | I10: =CONCATENATE(B10," ",C10) -> Layla Terrell
A11: 10 | B11: Bernardine | C11: Houston | D11: bernardine.houston@bikes.shop | E11: (972) 530-5557 | F11: 1 | G11: 3 | H11: 7 | I11: =CONCATENATE(B11," ",C11) -> Bernardine Houston
